<?xml version="1.0" encoding="utf-8"?>
<robot name="odrive_actuators">

    <link name="world" />

    <link name="linkYZ0" />
    <joint name="jointYZ0" type="continuous">
        <parent link="world"/>
        <child link="link0"/>
        <axis xyz="0 0 1"/>
    </joint>

    <link name="linkYZ1" />
    <joint name="jointYZ1" type="continuous">
        <parent link="world"/>
        <child link="link1"/>
        <axis xyz="0 0 1"/>
    </joint>

    <link name="linkX" />
    <joint name="jointX" type="continuous">
        <parent link="world"/>
        <child link="link1"/>
        <axis xyz="0 0 1"/>
    </joint>

  <ros2_control name="TBOT_actuators" type="system">
    <hardware>
      <plugin>odrive_hardware_interface/ODriveHardwareInterface</plugin>
    </hardware>
    <sensor name="odrv0">
      <param name="serial_number">207f34a25748</param>
    </sensor>

    <joint name="jointYZ0">
      <param name="serial_number">207f34a25748</param>
      <param name="axis">0</param>
      <param name="enable_watchdog">0</param>
      <param name="watchdog_timeout">0.1</param>
    </joint>

    <joint name="jointYZ1">
      <param name="serial_number">207f34a25748</param>
      <param name="axis">1</param>
      <param name="enable_watchdog">0</param>
      <param name="watchdog_timeout">0.1</param>
    </joint>

  </ros2_control>

  <ros2_control name="X_actuator" type="system">
    <hardware>
      <plugin>odrive_hardware_interface/ODriveHardwareInterface</plugin>
    </hardware>
    <sensor name="odrv1">
      <param name="serial_number">204f347c5748</param>
    </sensor>
    
    <joint name="jointX">
      <param name="serial_number">204f347c5748</param>
      <param name="axis">0</param>
      <param name="enable_watchdog">0</param>
      <param name="watchdog_timeout">0.1</param>
    </joint>
    
  </ros2_control>

</robot>
